<def f='include/c++/9/exception' l='49' type='void std::bad_exception::bad_exception()'/>
<use f='boost-1.85.0/libs/system/include/boost/system/result.hpp' l='65' u='c' c='_ZN5boost6system26throw_exception_from_errorERKNSt15__exception_ptr13exception_ptrERKNS_15source_locationE'/>
