<dec f='include/c++/9/bits/exception_ptr.h' l='98' type='void std::__exception_ptr::exception_ptr::exception_ptr(const std::__exception_ptr::exception_ptr &amp; )'/>
<use f='include/c++/9/bits/nested_exception.h' l='70' u='c' c='_ZNKSt16nested_exception14rethrow_nestedEv'/>
<use f='include/c++/9/bits/nested_exception.h' l='76' u='c' c='_ZNKSt16nested_exception10nested_ptrEv'/>
<use f='include/c++/9/future' l='719' u='c' c='_ZNKSt14__basic_future13_M_get_resultEv'/>
<use f='boost-1.85.0/libs/system/include/boost/system/result.hpp' l='61' u='c' c='_ZN5boost6system26throw_exception_from_errorERKNSt15__exception_ptr13exception_ptrERKNS_15source_locationE'/>
<use f='boost-1.85.0/libs/exception/include/boost/exception/detail/exception_ptr.hpp' l='53' u='c' c='_ZN5boost16exception_detail25std_exception_ptr_wrapperC1ERKNSt15__exception_ptr13exception_ptrE'/>
<use f='boost-1.85.0/libs/exception/include/boost/exception/detail/exception_ptr.hpp' l='550' u='c' c='_ZN5boost16exception_detail18rethrow_exception_ERKNS_13exception_ptrE'/>
<use f='boost-1.85.0/libs/asio/include/boost/asio/impl/multiple_exceptions.ipp' l='39' u='c' c='_ZNK5boost4asio19multiple_exceptions15first_exceptionEv'/>
<use f='boost-1.85.0/libs/asio/include/boost/asio/detail/thread_info_base.hpp' l='210' u='c' c='_ZN5boost4asio6detail16thread_info_base25capture_current_exceptionEv'/>
<use f='boost-1.85.0/libs/asio/include/boost/asio/detail/thread_info_base.hpp' l='227' u='c' c='_ZN5boost4asio6detail16thread_info_base25rethrow_pending_exceptionEv'/>
