<inh f='include/c++/9/bits/exception.h' l='60' c='std::exception'/>
<def f='boost-1.85.0/libs/exception/include/boost/exception/detail/exception_ptr.hpp' l='47' ll='62'/>
<use f='boost-1.85.0/libs/exception/include/boost/exception/detail/exception_ptr.hpp' l='67' c='_ZN5boost16exception_detail18wrap_exception_ptrERKNSt15__exception_ptr13exception_ptrE'/>
<use f='boost-1.85.0/libs/exception/include/boost/exception/detail/exception_ptr.hpp' l='547' c='_ZN5boost16exception_detail18rethrow_exception_ERKNS_13exception_ptrE'/>
<size>16</size>
<mbr r='boost::exception_detail::std_exception_ptr_wrapper::p' o='64' t='std::exception_ptr'/>
<fun r='_ZN5boost16exception_detail25std_exception_ptr_wrapperC1ERKNSt15__exception_ptr13exception_ptrE'/>
<fun r='_ZN5boost16exception_detail25std_exception_ptr_wrapperC1EONSt15__exception_ptr13exception_ptrE'/>
